package com.benny.world;

import java.util.Random;

import com.google.common.eventbus.Subscribe;

import cpw.mods.fml.common.IWorldGenerator;
import net.minecraft.block.Block;
import net.minecraft.block.material.Material;
import net.minecraft.entity.EntityLivingBase;
import net.minecraft.init.Blocks;
import net.minecraft.item.ItemStack;
import net.minecraft.world.World;
import net.minecraft.world.chunk.IChunkProvider;

public class OwleryInstantStructure extends Block implements IWorldGenerator{
public static void MainRegistry() {
}Blocks b;

public OwleryInstantStructure(Material material){	
	super(material);
	System.out.println("Before break");
}

@Subscribe
public void onBlockBreak(World world, Random random, int x, int y, int z, EntityLivingBase entity, ItemStack itemstack)
{ 
System.out.println("Making Structure");
//Sets the block to air on the x, y, and z coords from where you placed the block
world.setBlockToAir(x, y, z);

//Sets the block on the x, y, and z coords starting from where you placed the block
world.setBlock(x + 0, y + 0, z + 0, Blocks.dirt, 0, 3);
world.setBlock(x + 1, y + 0, z + 0, Blocks.dirt, 0, 3);
world.setBlock(x + 2, y + 0, z + 0, Blocks.dirt, 0, 3);
world.setBlock(x + 4, y + 0, z + 0, Blocks.dirt, 0, 3);
world.setBlock(x + 5, y + 0, z + 0, Blocks.dirt, 0, 3);
world.setBlock(x + 6, y + 0, z + 0, Blocks.dirt, 0, 3);
world.setBlock(x + 7, y + 0, z + 0, Blocks.dirt, 0, 3);
world.setBlock(x + 0, y + 0, z + 1, Blocks.dirt, 0, 3);
world.setBlock(x + 1, y + 0, z + 1, Blocks.dirt, 0, 3);
world.setBlock(x + 2, y + 0, z + 1, Blocks.dirt, 0, 3);
world.setBlock(x + 3, y + 0, z + 1, Blocks.dirt, 0, 3);
world.setBlock(x + 4, y + 0, z + 1, Blocks.dirt, 0, 3);
world.setBlock(x + 5, y + 0, z + 1, Blocks.dirt, 0, 3);
world.setBlock(x + 6, y + 0, z + 1, Blocks.dirt, 0, 3);
world.setBlock(x + 7, y + 0, z + 1, Blocks.dirt, 0, 3);
world.setBlock(x + 0, y + 0, z + 2, Blocks.dirt, 0, 3);
world.setBlock(x + 1, y + 0, z + 2, Blocks.dirt, 0, 3);
world.setBlock(x + 2, y + 0, z + 2, Blocks.dirt, 0, 3);
world.setBlock(x + 3, y + 0, z + 2, Blocks.dirt, 0, 3);
world.setBlock(x + 4, y + 0, z + 2, Blocks.dirt, 0, 3);
world.setBlock(x + 5, y + 0, z + 2, Blocks.dirt, 0, 3);
world.setBlock(x + 6, y + 0, z + 2, Blocks.dirt, 0, 3);
world.setBlock(x + 7, y + 0, z + 2, Blocks.dirt, 0, 3);
world.setBlock(x + 0, y + 0, z + 3, Blocks.dirt, 0, 3);
world.setBlock(x + 1, y + 0, z + 3, Blocks.grass, 0, 3);
world.setBlock(x + 2, y + 0, z + 3, Blocks.water, 0, 3);
world.setBlock(x + 3, y + 0, z + 3, Blocks.dirt, 0, 3);
world.setBlock(x + 4, y + 0, z + 3, Blocks.dirt, 0, 3);
world.setBlock(x + 5, y + 0, z + 3, Blocks.dirt, 0, 3);
world.setBlock(x + 6, y + 0, z + 3, Blocks.dirt, 0, 3);
world.setBlock(x + 7, y + 0, z + 3, Blocks.dirt, 0, 3);
world.setBlock(x + 0, y + 0, z + 4, Blocks.dirt, 0, 3);
world.setBlock(x + 1, y + 0, z + 4, Blocks.dirt, 0, 3);
world.setBlock(x + 2, y + 0, z + 4, Blocks.dirt, 0, 3);
world.setBlock(x + 3, y + 0, z + 4, Blocks.dirt, 0, 3);
world.setBlock(x + 4, y + 0, z + 4, Blocks.dirt, 0, 3);
world.setBlock(x + 5, y + 0, z + 4, Blocks.dirt, 0, 3);
world.setBlock(x + 6, y + 0, z + 4, Blocks.dirt, 0, 3);
world.setBlock(x + 7, y + 0, z + 4, Blocks.dirt, 0, 3);
world.setBlock(x + 0, y + 0, z + 5, Blocks.dirt, 0, 3);
world.setBlock(x + 1, y + 0, z + 5, Blocks.dirt, 0, 3);
world.setBlock(x + 2, y + 0, z + 5, Blocks.dirt, 0, 3);
world.setBlock(x + 3, y + 0, z + 5, Blocks.dirt, 0, 3);
world.setBlock(x + 4, y + 0, z + 5, Blocks.dirt, 0, 3);
world.setBlock(x + 5, y + 0, z + 5, Blocks.dirt, 0, 3);
world.setBlock(x + 6, y + 0, z + 5, Blocks.dirt, 0, 3);
world.setBlock(x + 7, y + 0, z + 5, Blocks.dirt, 0, 3);
world.setBlock(x + 0, y + 1, z + 0, Blocks.dirt, 0, 3);
world.setBlock(x + 1, y + 1, z + 0, Blocks.grass, 0, 3);
world.setBlock(x + 2, y + 1, z + 0, Blocks.grass, 0, 3);
world.setBlock(x + 3, y + 1, z + 0, Blocks.grass, 0, 3);
world.setBlock(x + 4, y + 1, z + 0, Blocks.grass, 0, 3);
world.setBlock(x + 5, y + 1, z + 0, Blocks.dirt, 0, 3);
world.setBlock(x + 6, y + 1, z + 0, Blocks.grass, 0, 3);
world.setBlock(x + 7, y + 1, z + 0, Blocks.dirt, 0, 3);
world.setBlock(x + 0, y + 1, z + 1, Blocks.grass, 0, 3);
world.setBlock(x + 1, y + 1, z + 1, Blocks.grass, 0, 3);
world.setBlock(x + 2, y + 1, z + 1, Blocks.grass, 0, 3);
world.setBlock(x + 3, y + 1, z + 1, Blocks.grass, 0, 3);
world.setBlock(x + 4, y + 1, z + 1, Blocks.grass, 0, 3);
world.setBlock(x + 5, y + 1, z + 1, Blocks.grass, 0, 3);
world.setBlock(x + 6, y + 1, z + 1, Blocks.grass, 0, 3);
world.setBlock(x + 7, y + 1, z + 1, Blocks.grass, 0, 3);
world.setBlock(x + 0, y + 1, z + 2, Blocks.grass, 0, 3);
world.setBlock(x + 1, y + 1, z + 2, Blocks.grass, 0, 3);
world.setBlock(x + 2, y + 1, z + 2, Blocks.air, 0, 3);
world.setBlock(x + 3, y + 1, z + 2, Blocks.grass, 0, 3);
world.setBlock(x + 4, y + 1, z + 2, Blocks.grass, 0, 3);
world.setBlock(x + 5, y + 1, z + 2, Blocks.grass, 0, 3);
world.setBlock(x + 6, y + 1, z + 2, Blocks.grass, 0, 3);
world.setBlock(x + 7, y + 1, z + 2, Blocks.grass, 0, 3);
world.setBlock(x + 0, y + 1, z + 3, Blocks.grass, 0, 3);
world.setBlock(x + 1, y + 1, z + 3, Blocks.air, 0, 3);
world.setBlock(x + 2, y + 1, z + 3, Blocks.air, 0, 3);
world.setBlock(x + 3, y + 1, z + 3, Blocks.air, 0, 3);
world.setBlock(x + 4, y + 1, z + 3, Blocks.grass, 0, 3);
world.setBlock(x + 5, y + 1, z + 3, Blocks.grass, 0, 3);
world.setBlock(x + 6, y + 1, z + 3, Blocks.grass, 0, 3);
world.setBlock(x + 7, y + 1, z + 3, Blocks.grass, 0, 3);
world.setBlock(x + 0, y + 1, z + 4, Blocks.grass, 0, 3);
world.setBlock(x + 1, y + 1, z + 4, Blocks.grass, 0, 3);
world.setBlock(x + 2, y + 1, z + 4, Blocks.air, 0, 3);
world.setBlock(x + 3, y + 1, z + 4, Blocks.grass, 0, 3);
world.setBlock(x + 4, y + 1, z + 4, Blocks.grass, 0, 3);
world.setBlock(x + 5, y + 1, z + 4, Blocks.grass, 0, 3);
world.setBlock(x + 6, y + 1, z + 4, Blocks.grass, 0, 3);
world.setBlock(x + 7, y + 1, z + 4, Blocks.grass, 0, 3);
world.setBlock(x + 0, y + 1, z + 5, Blocks.dirt, 0, 3);
world.setBlock(x + 1, y + 1, z + 5, Blocks.grass, 0, 3);
world.setBlock(x + 2, y + 1, z + 5, Blocks.grass, 0, 3);
world.setBlock(x + 3, y + 1, z + 5, Blocks.grass, 0, 3);
world.setBlock(x + 4, y + 1, z + 5, Blocks.grass, 0, 3);
world.setBlock(x + 5, y + 1, z + 5, Blocks.grass, 0, 3);
world.setBlock(x + 6, y + 1, z + 5, Blocks.grass, 0, 3);
world.setBlock(x + 7, y + 1, z + 5, Blocks.dirt, 0, 3);
world.setBlock(x + 0, y + 2, z + 0, Blocks.log2, 1, 3);
world.setBlock(x + 1, y + 2, z + 0, Blocks.spruce_stairs, 6, 3);
world.setBlock(x + 2, y + 2, z + 0, Blocks.spruce_stairs, 6, 3);
world.setBlock(x + 3, y + 2, z + 0, Blocks.spruce_stairs, 6, 3);
world.setBlock(x + 4, y + 2, z + 0, Blocks.spruce_stairs, 6, 3);
world.setBlock(x + 5, y + 2, z + 0, Blocks.log2, 1, 3);
world.setBlock(x + 6, y + 2, z + 0, Blocks.wooden_door, 1, 3);
world.setBlock(x + 7, y + 2, z + 0, Blocks.log2, 1, 3);
world.setBlock(x + 0, y + 2, z + 1, Blocks.spruce_stairs, 4, 3);
world.setBlock(x + 1, y + 2, z + 1, Blocks.air, 0, 3);
world.setBlock(x + 2, y + 2, z + 1, Blocks.air, 0, 3);
world.setBlock(x + 3, y + 2, z + 1, Blocks.air, 0, 3);
world.setBlock(x + 4, y + 2, z + 1, Blocks.tallgrass, 1, 3);
world.setBlock(x + 5, y + 2, z + 1, Blocks.tallgrass, 1, 3);
world.setBlock(x + 6, y + 2, z + 1, Blocks.air, 0, 3);
world.setBlock(x + 7, y + 2, z + 1, Blocks.spruce_stairs, 5, 3);
world.setBlock(x + 0, y + 2, z + 2, Blocks.spruce_stairs, 4, 3);
world.setBlock(x + 1, y + 2, z + 2, Blocks.air, 0, 3);
world.setBlock(x + 2, y + 2, z + 2, Blocks.air, 0, 3);
world.setBlock(x + 3, y + 2, z + 2, Blocks.air, 0, 3);
world.setBlock(x + 4, y + 2, z + 2, Blocks.air, 0, 3);
world.setBlock(x + 5, y + 2, z + 2, Blocks.tallgrass, 1, 3);
world.setBlock(x + 6, y + 2, z + 2, Blocks.tallgrass, 1, 3);
world.setBlock(x + 7, y + 2, z + 2, Blocks.spruce_stairs, 5, 3);
world.setBlock(x + 0, y + 2, z + 3, Blocks.spruce_stairs, 4, 3);
world.setBlock(x + 1, y + 2, z + 3, Blocks.air, 0, 3);
world.setBlock(x + 2, y + 2, z + 3, Blocks.air, 0, 3);
world.setBlock(x + 3, y + 2, z + 3, Blocks.air, 0, 3);
world.setBlock(x + 4, y + 2, z + 3, Blocks.air, 0, 3);
world.setBlock(x + 5, y + 2, z + 3, Blocks.tallgrass, 1, 3);
world.setBlock(x + 6, y + 2, z + 3, Blocks.tallgrass, 1, 3);
world.setBlock(x + 7, y + 2, z + 3, Blocks.spruce_stairs, 5, 3);
world.setBlock(x + 0, y + 2, z + 4, Blocks.spruce_stairs, 4, 3);
world.setBlock(x + 1, y + 2, z + 4, Blocks.air, 0, 3);
world.setBlock(x + 2, y + 2, z + 4, Blocks.air, 0, 3);
world.setBlock(x + 3, y + 2, z + 4, Blocks.air, 0, 3);
world.setBlock(x + 4, y + 2, z + 4, Blocks.yellow_flower, 0, 3);
world.setBlock(x + 5, y + 2, z + 4, Blocks.tallgrass, 1, 3);
world.setBlock(x + 6, y + 2, z + 4, Blocks.tallgrass, 1, 3);
world.setBlock(x + 7, y + 2, z + 4, Blocks.spruce_stairs, 5, 3);
world.setBlock(x + 0, y + 2, z + 5, Blocks.log2, 1, 3);
world.setBlock(x + 1, y + 2, z + 5, Blocks.spruce_stairs, 7, 3);
world.setBlock(x + 2, y + 2, z + 5, Blocks.spruce_stairs, 7, 3);
world.setBlock(x + 3, y + 2, z + 5, Blocks.spruce_stairs, 7, 3);
world.setBlock(x + 4, y + 2, z + 5, Blocks.spruce_stairs, 7, 3);
world.setBlock(x + 5, y + 2, z + 5, Blocks.spruce_stairs, 7, 3);
world.setBlock(x + 6, y + 2, z + 5, Blocks.spruce_stairs, 7, 3);
world.setBlock(x + 7, y + 2, z + 5, Blocks.log2, 1, 3);
world.setBlock(x + 0, y + 3, z + 0, Blocks.log2, 1, 3);
world.setBlock(x + 1, y + 3, z + 0, Blocks.stained_glass, 7, 3);
world.setBlock(x + 2, y + 3, z + 0, Blocks.stained_glass, 7, 3);
world.setBlock(x + 3, y + 3, z + 0, Blocks.stained_glass, 7, 3);
world.setBlock(x + 4, y + 3, z + 0, Blocks.stained_glass, 7, 3);
world.setBlock(x + 5, y + 3, z + 0, Blocks.log2, 1, 3);
world.setBlock(x + 6, y + 3, z + 0, Blocks.wooden_door, 8, 3);
world.setBlock(x + 7, y + 3, z + 0, Blocks.log2, 1, 3);
world.setBlock(x + 0, y + 3, z + 1, Blocks.stained_glass, 7, 3);
world.setBlock(x + 1, y + 3, z + 1, Blocks.air, 0, 3);
world.setBlock(x + 2, y + 3, z + 1, Blocks.air, 0, 3);
world.setBlock(x + 3, y + 3, z + 1, Blocks.air, 0, 3);
world.setBlock(x + 4, y + 3, z + 1, Blocks.air, 0, 3);
world.setBlock(x + 5, y + 3, z + 1, Blocks.air, 0, 3);
world.setBlock(x + 6, y + 3, z + 1, Blocks.air, 0, 3);
world.setBlock(x + 7, y + 3, z + 1, Blocks.stained_glass, 7, 3);
world.setBlock(x + 0, y + 3, z + 2, Blocks.stained_glass, 7, 3);
world.setBlock(x + 1, y + 3, z + 2, Blocks.air, 0, 3);
world.setBlock(x + 2, y + 3, z + 2, Blocks.air, 0, 3);
world.setBlock(x + 3, y + 3, z + 2, Blocks.air, 0, 3);
world.setBlock(x + 4, y + 3, z + 2, Blocks.air, 0, 3);
world.setBlock(x + 5, y + 3, z + 2, Blocks.air, 0, 3);
world.setBlock(x + 6, y + 3, z + 2, Blocks.air, 0, 3);
world.setBlock(x + 7, y + 3, z + 2, Blocks.stained_glass, 7, 3);
world.setBlock(x + 0, y + 3, z + 3, Blocks.stained_glass, 7, 3);
world.setBlock(x + 1, y + 3, z + 3, Blocks.air, 0, 3);
world.setBlock(x + 2, y + 3, z + 3, Blocks.air, 0, 3);
world.setBlock(x + 3, y + 3, z + 3, Blocks.air, 0, 3);
world.setBlock(x + 4, y + 3, z + 3, Blocks.air, 0, 3);
world.setBlock(x + 5, y + 3, z + 3, Blocks.air, 0, 3);
world.setBlock(x + 6, y + 3, z + 3, Blocks.air, 0, 3);
world.setBlock(x + 7, y + 3, z + 3, Blocks.stained_glass, 7, 3);
world.setBlock(x + 0, y + 3, z + 4, Blocks.stained_glass, 7, 3);
world.setBlock(x + 1, y + 3, z + 4, Blocks.air, 0, 3);
world.setBlock(x + 2, y + 3, z + 4, Blocks.air, 0, 3);
world.setBlock(x + 3, y + 3, z + 4, Blocks.air, 0, 3);
world.setBlock(x + 4, y + 3, z + 4, Blocks.air, 0, 3);
world.setBlock(x + 5, y + 3, z + 4, Blocks.air, 0, 3);
world.setBlock(x + 6, y + 3, z + 4, Blocks.air, 0, 3);
world.setBlock(x + 7, y + 3, z + 4, Blocks.stained_glass, 7, 3);
world.setBlock(x + 0, y + 3, z + 5, Blocks.log2, 1, 3);
world.setBlock(x + 1, y + 3, z + 5, Blocks.stained_glass, 7, 3);
world.setBlock(x + 2, y + 3, z + 5, Blocks.stained_glass, 7, 3);
world.setBlock(x + 3, y + 3, z + 5, Blocks.stained_glass, 7, 3);
world.setBlock(x + 4, y + 3, z + 5, Blocks.stained_glass, 7, 3);
world.setBlock(x + 5, y + 3, z + 5, Blocks.stained_glass, 7, 3);
world.setBlock(x + 6, y + 3, z + 5, Blocks.stained_glass, 7, 3);
world.setBlock(x + 7, y + 3, z + 5, Blocks.log2, 1, 3);
world.setBlock(x + 0, y + 4, z + 0, Blocks.log2, 1, 3);
world.setBlock(x + 1, y + 4, z + 0, Blocks.stained_glass, 7, 3);
world.setBlock(x + 2, y + 4, z + 0, Blocks.stained_glass, 7, 3);
world.setBlock(x + 3, y + 4, z + 0, Blocks.stained_glass, 7, 3);
world.setBlock(x + 4, y + 4, z + 0, Blocks.stained_glass, 7, 3);
world.setBlock(x + 5, y + 4, z + 0, Blocks.log2, 1, 3);
world.setBlock(x + 6, y + 4, z + 0, Blocks.log2, 5, 3);
world.setBlock(x + 7, y + 4, z + 0, Blocks.log2, 1, 3);
world.setBlock(x + 0, y + 4, z + 1, Blocks.stained_glass, 7, 3);
world.setBlock(x + 1, y + 4, z + 1, Blocks.air, 0, 3);
world.setBlock(x + 2, y + 4, z + 1, Blocks.air, 0, 3);
world.setBlock(x + 3, y + 4, z + 1, Blocks.air, 0, 3);
world.setBlock(x + 4, y + 4, z + 1, Blocks.air, 0, 3);
world.setBlock(x + 5, y + 4, z + 1, Blocks.air, 0, 3);
world.setBlock(x + 6, y + 4, z + 1, Blocks.air, 0, 3);
world.setBlock(x + 7, y + 4, z + 1, Blocks.stained_glass, 7, 3);
world.setBlock(x + 0, y + 4, z + 2, Blocks.stained_glass, 7, 3);
world.setBlock(x + 1, y + 4, z + 2, Blocks.air, 0, 3);
world.setBlock(x + 2, y + 4, z + 2, Blocks.air, 0, 3);
world.setBlock(x + 3, y + 4, z + 2, Blocks.air, 0, 3);
world.setBlock(x + 4, y + 4, z + 2, Blocks.air, 0, 3);
world.setBlock(x + 5, y + 4, z + 2, Blocks.air, 0, 3);
world.setBlock(x + 6, y + 4, z + 2, Blocks.air, 0, 3);
world.setBlock(x + 7, y + 4, z + 2, Blocks.stained_glass, 7, 3);
world.setBlock(x + 0, y + 4, z + 3, Blocks.stained_glass, 7, 3);
world.setBlock(x + 1, y + 4, z + 3, Blocks.air, 0, 3);
world.setBlock(x + 2, y + 4, z + 3, Blocks.air, 0, 3);
world.setBlock(x + 3, y + 4, z + 3, Blocks.air, 0, 3);
world.setBlock(x + 4, y + 4, z + 3, Blocks.air, 0, 3);
world.setBlock(x + 5, y + 4, z + 3, Blocks.air, 0, 3);
world.setBlock(x + 6, y + 4, z + 3, Blocks.air, 0, 3);
world.setBlock(x + 7, y + 4, z + 3, Blocks.stained_glass, 7, 3);
world.setBlock(x + 0, y + 4, z + 4, Blocks.stained_glass, 7, 3);
world.setBlock(x + 1, y + 4, z + 4, Blocks.air, 0, 3);
world.setBlock(x + 2, y + 4, z + 4, Blocks.air, 0, 3);
world.setBlock(x + 3, y + 4, z + 4, Blocks.air, 0, 3);
world.setBlock(x + 4, y + 4, z + 4, Blocks.air, 0, 3);
world.setBlock(x + 5, y + 4, z + 4, Blocks.air, 0, 3);
world.setBlock(x + 6, y + 4, z + 4, Blocks.air, 0, 3);
world.setBlock(x + 7, y + 4, z + 4, Blocks.stained_glass, 7, 3);
world.setBlock(x + 0, y + 4, z + 5, Blocks.log2, 1, 3);
world.setBlock(x + 1, y + 4, z + 5, Blocks.stained_glass, 7, 3);
world.setBlock(x + 2, y + 4, z + 5, Blocks.stained_glass, 7, 3);
world.setBlock(x + 3, y + 4, z + 5, Blocks.stained_glass, 7, 3);
world.setBlock(x + 4, y + 4, z + 5, Blocks.stained_glass, 7, 3);
world.setBlock(x + 5, y + 4, z + 5, Blocks.stained_glass, 7, 3);
world.setBlock(x + 6, y + 4, z + 5, Blocks.stained_glass, 7, 3);
world.setBlock(x + 7, y + 4, z + 5, Blocks.log2, 1, 3);
world.setBlock(x + 0, y + 5, z + 0, Blocks.spruce_stairs, 0, 3);
world.setBlock(x + 1, y + 5, z + 0, Blocks.spruce_stairs, 2, 3);
world.setBlock(x + 2, y + 5, z + 0, Blocks.spruce_stairs, 2, 3);
world.setBlock(x + 3, y + 5, z + 0, Blocks.spruce_stairs, 2, 3);
world.setBlock(x + 4, y + 5, z + 0, Blocks.spruce_stairs, 2, 3);
world.setBlock(x + 5, y + 5, z + 0, Blocks.spruce_stairs, 2, 3);
world.setBlock(x + 6, y + 5, z + 0, Blocks.spruce_stairs, 2, 3);
world.setBlock(x + 7, y + 5, z + 0, Blocks.spruce_stairs, 1, 3);
world.setBlock(x + 0, y + 5, z + 1, Blocks.spruce_stairs, 0, 3);
world.setBlock(x + 1, y + 5, z + 1, Blocks.wooden_slab, 9, 3);
world.setBlock(x + 2, y + 5, z + 1, Blocks.wooden_slab, 9, 3);
world.setBlock(x + 3, y + 5, z + 1, Blocks.wooden_slab, 9, 3);
world.setBlock(x + 4, y + 5, z + 1, Blocks.wooden_slab, 9, 3);
world.setBlock(x + 5, y + 5, z + 1, Blocks.wooden_slab, 9, 3);
world.setBlock(x + 6, y + 5, z + 1, Blocks.wooden_slab, 9, 3);
world.setBlock(x + 7, y + 5, z + 1, Blocks.spruce_stairs, 1, 3);
world.setBlock(x + 0, y + 5, z + 2, Blocks.spruce_stairs, 0, 3);
world.setBlock(x + 1, y + 5, z + 2, Blocks.wooden_slab, 9, 3);
world.setBlock(x + 2, y + 5, z + 2, Blocks.air, 0, 3);
world.setBlock(x + 3, y + 5, z + 2, Blocks.air, 0, 3);
world.setBlock(x + 4, y + 5, z + 2, Blocks.air, 0, 3);
world.setBlock(x + 5, y + 5, z + 2, Blocks.air, 0, 3);
world.setBlock(x + 6, y + 5, z + 2, Blocks.wooden_slab, 9, 3);
world.setBlock(x + 7, y + 5, z + 2, Blocks.spruce_stairs, 1, 3);
world.setBlock(x + 0, y + 5, z + 3, Blocks.spruce_stairs, 0, 3);
world.setBlock(x + 1, y + 5, z + 3, Blocks.wooden_slab, 9, 3);
world.setBlock(x + 2, y + 5, z + 3, Blocks.air, 0, 3);
world.setBlock(x + 3, y + 5, z + 3, Blocks.air, 0, 3);
world.setBlock(x + 4, y + 5, z + 3, Blocks.air, 0, 3);
world.setBlock(x + 5, y + 5, z + 3, Blocks.air, 0, 3);
world.setBlock(x + 6, y + 5, z + 3, Blocks.wooden_slab, 9, 3);
world.setBlock(x + 7, y + 5, z + 3, Blocks.spruce_stairs, 1, 3);
world.setBlock(x + 0, y + 5, z + 4, Blocks.spruce_stairs, 0, 3);
world.setBlock(x + 1, y + 5, z + 4, Blocks.wooden_slab, 9, 3);
world.setBlock(x + 2, y + 5, z + 4, Blocks.wooden_slab, 9, 3);
world.setBlock(x + 3, y + 5, z + 4, Blocks.wooden_slab, 9, 3);
world.setBlock(x + 4, y + 5, z + 4, Blocks.wooden_slab, 9, 3);
world.setBlock(x + 5, y + 5, z + 4, Blocks.wooden_slab, 9, 3);
world.setBlock(x + 6, y + 5, z + 4, Blocks.wooden_slab, 9, 3);
world.setBlock(x + 7, y + 5, z + 4, Blocks.spruce_stairs, 1, 3);
world.setBlock(x + 0, y + 5, z + 5, Blocks.spruce_stairs, 3, 3);
world.setBlock(x + 1, y + 5, z + 5, Blocks.spruce_stairs, 3, 3);
world.setBlock(x + 2, y + 5, z + 5, Blocks.spruce_stairs, 3, 3);
world.setBlock(x + 3, y + 5, z + 5, Blocks.spruce_stairs, 3, 3);
world.setBlock(x + 4, y + 5, z + 5, Blocks.spruce_stairs, 3, 3);
world.setBlock(x + 5, y + 5, z + 5, Blocks.spruce_stairs, 3, 3);
world.setBlock(x + 6, y + 5, z + 5, Blocks.spruce_stairs, 3, 3);
world.setBlock(x + 7, y + 5, z + 5, Blocks.spruce_stairs, 3, 3);
world.setBlock(x + 0, y + 6, z + 0, Blocks.air, 0, 3);
world.setBlock(x + 1, y + 6, z + 0, Blocks.air, 0, 3);
world.setBlock(x + 2, y + 6, z + 0, Blocks.air, 0, 3);
world.setBlock(x + 3, y + 6, z + 0, Blocks.air, 0, 3);
world.setBlock(x + 4, y + 6, z + 0, Blocks.air, 0, 3);
world.setBlock(x + 5, y + 6, z + 0, Blocks.air, 0, 3);
world.setBlock(x + 6, y + 6, z + 0, Blocks.air, 0, 3);
world.setBlock(x + 7, y + 6, z + 0, Blocks.air, 0, 3);
world.setBlock(x + 0, y + 6, z + 1, Blocks.air, 0, 3);
world.setBlock(x + 1, y + 6, z + 1, Blocks.spruce_stairs, 2, 3);
world.setBlock(x + 2, y + 6, z + 1, Blocks.spruce_stairs, 2, 3);
world.setBlock(x + 3, y + 6, z + 1, Blocks.spruce_stairs, 2, 3);
world.setBlock(x + 4, y + 6, z + 1, Blocks.spruce_stairs, 2, 3);
world.setBlock(x + 5, y + 6, z + 1, Blocks.spruce_stairs, 2, 3);
world.setBlock(x + 6, y + 6, z + 1, Blocks.spruce_stairs, 2, 3);
world.setBlock(x + 7, y + 6, z + 1, Blocks.air, 0, 3);
world.setBlock(x + 0, y + 6, z + 2, Blocks.air, 0, 3);
world.setBlock(x + 1, y + 6, z + 2, Blocks.spruce_stairs, 0, 3);
world.setBlock(x + 2, y + 6, z + 2, Blocks.stained_glass, 15, 3);
world.setBlock(x + 3, y + 6, z + 2, Blocks.stained_glass, 15, 3);
world.setBlock(x + 4, y + 6, z + 2, Blocks.stained_glass, 15, 3);
world.setBlock(x + 5, y + 6, z + 2, Blocks.stained_glass, 15, 3);
world.setBlock(x + 6, y + 6, z + 2, Blocks.spruce_stairs, 1, 3);
world.setBlock(x + 7, y + 6, z + 2, Blocks.air, 0, 3);
world.setBlock(x + 0, y + 6, z + 3, Blocks.air, 0, 3);
world.setBlock(x + 1, y + 6, z + 3, Blocks.spruce_stairs, 0, 3);
world.setBlock(x + 2, y + 6, z + 3, Blocks.stained_glass, 15, 3);
world.setBlock(x + 3, y + 6, z + 3, Blocks.stained_glass, 15, 3);
world.setBlock(x + 4, y + 6, z + 3, Blocks.stained_glass, 15, 3);
world.setBlock(x + 5, y + 6, z + 3, Blocks.stained_glass, 15, 3);
world.setBlock(x + 6, y + 6, z + 3, Blocks.spruce_stairs, 1, 3);
world.setBlock(x + 7, y + 6, z + 3, Blocks.air, 0, 3);
world.setBlock(x + 0, y + 6, z + 4, Blocks.air, 0, 3);
world.setBlock(x + 1, y + 6, z + 4, Blocks.spruce_stairs, 0, 3);
world.setBlock(x + 2, y + 6, z + 4, Blocks.spruce_stairs, 3, 3);
world.setBlock(x + 3, y + 6, z + 4, Blocks.spruce_stairs, 3, 3);
world.setBlock(x + 4, y + 6, z + 4, Blocks.spruce_stairs, 3, 3);
world.setBlock(x + 5, y + 6, z + 4, Blocks.spruce_stairs, 3, 3);
world.setBlock(x + 6, y + 6, z + 4, Blocks.spruce_stairs, 3, 3);
world.setBlock(x + 7, y + 6, z + 4, Blocks.air, 0, 3);
world.setBlock(x + 0, y + 6, z + 5, Blocks.air, 0, 3);
world.setBlock(x + 1, y + 6, z + 5, Blocks.air, 0, 3);
world.setBlock(x + 2, y + 6, z + 5, Blocks.air, 0, 3);
world.setBlock(x + 3, y + 6, z + 5, Blocks.air, 0, 3);
world.setBlock(x + 4, y + 6, z + 5, Blocks.air, 0, 3);
world.setBlock(x + 5, y + 6, z + 5, Blocks.air, 0, 3);
world.setBlock(x + 6, y + 6, z + 5, Blocks.air, 0, 3);
world.setBlock(x + 7, y + 6, z + 5, Blocks.air, 0, 3);
world.setBlock(x + 0, y + 7, z + 0, Blocks.air, 0, 3);
world.setBlock(x + 1, y + 7, z + 0, Blocks.air, 0, 3);
world.setBlock(x + 2, y + 7, z + 0, Blocks.air, 0, 3);
world.setBlock(x + 3, y + 7, z + 0, Blocks.air, 0, 3);
world.setBlock(x + 4, y + 7, z + 0, Blocks.air, 0, 3);
world.setBlock(x + 5, y + 7, z + 0, Blocks.air, 0, 3);
world.setBlock(x + 6, y + 7, z + 0, Blocks.air, 0, 3);
world.setBlock(x + 7, y + 7, z + 0, Blocks.air, 0, 3);
world.setBlock(x + 0, y + 7, z + 1, Blocks.air, 0, 3);
world.setBlock(x + 1, y + 7, z + 1, Blocks.air, 0, 3);
world.setBlock(x + 2, y + 7, z + 1, Blocks.air, 0, 3);
world.setBlock(x + 3, y + 7, z + 1, Blocks.air, 0, 3);
world.setBlock(x + 4, y + 7, z + 1, Blocks.air, 0, 3);
world.setBlock(x + 5, y + 7, z + 1, Blocks.air, 0, 3);
world.setBlock(x + 6, y + 7, z + 1, Blocks.air, 0, 3);
world.setBlock(x + 7, y + 7, z + 1, Blocks.air, 0, 3);
world.setBlock(x + 0, y + 7, z + 2, Blocks.air, 0, 3);
world.setBlock(x + 1, y + 7, z + 2, Blocks.air, 0, 3);
world.setBlock(x + 2, y + 7, z + 2, Blocks.air, 0, 3);
world.setBlock(x + 3, y + 7, z + 2, Blocks.air, 0, 3);
world.setBlock(x + 4, y + 7, z + 2, Blocks.air, 0, 3);
world.setBlock(x + 5, y + 7, z + 2, Blocks.air, 0, 3);
world.setBlock(x + 6, y + 7, z + 2, Blocks.air, 0, 3);
world.setBlock(x + 7, y + 7, z + 2, Blocks.air, 0, 3);
world.setBlock(x + 0, y + 7, z + 3, Blocks.air, 0, 3);
world.setBlock(x + 1, y + 7, z + 3, Blocks.air, 0, 3);
world.setBlock(x + 2, y + 7, z + 3, Blocks.air, 0, 3);
world.setBlock(x + 3, y + 7, z + 3, Blocks.air, 0, 3);
world.setBlock(x + 4, y + 7, z + 3, Blocks.air, 0, 3);
world.setBlock(x + 5, y + 7, z + 3, Blocks.air, 0, 3);
world.setBlock(x + 6, y + 7, z + 3, Blocks.air, 0, 3);
world.setBlock(x + 7, y + 7, z + 3, Blocks.air, 0, 3);
world.setBlock(x + 0, y + 7, z + 4, Blocks.air, 0, 3);
world.setBlock(x + 1, y + 7, z + 4, Blocks.air, 0, 3);
world.setBlock(x + 2, y + 7, z + 4, Blocks.air, 0, 3);
world.setBlock(x + 3, y + 7, z + 4, Blocks.air, 0, 3);
world.setBlock(x + 4, y + 7, z + 4, Blocks.air, 0, 3);
world.setBlock(x + 5, y + 7, z + 4, Blocks.air, 0, 3);
world.setBlock(x + 6, y + 7, z + 4, Blocks.air, 0, 3);
world.setBlock(x + 7, y + 7, z + 4, Blocks.air, 0, 3);
world.setBlock(x + 0, y + 7, z + 5, Blocks.air, 0, 3);
world.setBlock(x + 1, y + 7, z + 5, Blocks.air, 0, 3);
world.setBlock(x + 2, y + 7, z + 5, Blocks.air, 0, 3);
world.setBlock(x + 3, y + 7, z + 5, Blocks.air, 0, 3);
world.setBlock(x + 4, y + 7, z + 5, Blocks.air, 0, 3);
world.setBlock(x + 5, y + 7, z + 5, Blocks.air, 0, 3);
world.setBlock(x + 6, y + 7, z + 5, Blocks.air, 0, 3);
world.setBlock(x + 7, y + 7, z + 5, Blocks.air, 0, 3);

//Sets the block(with set metadata) on the x, y, and z coords from where you placed the block
world.setBlock(1, y, z, b.planks, 2, 2); //This is for birch planks, if you want other planks, search 'Minecraft Block Metadata' in google or find it on the MinecraftWiki
}


@Override
public void generate(Random random, int chunkX, int chunkZ, World world, IChunkProvider chunkGenerator,
		IChunkProvider chunkProvider) {
	// TODO Auto-generated method stub
	
}


		
	}

